Workbook

Sheet Léeme
A1: Unidad 2 · Partida doble (base abierta de ingeniería)
A2: Hojas: diario, mayor y balance de comprobación del caso Estampa Sur (marzo) y del ejemplo Capa a Capa (mayo de 2026).
A3: Todo se calcula con fórmulas desde la hoja del diario: si cambias un monto, el mayor y la comprobación se actualizan.
A4: Montos en pesos, IVA 19 % redondeado al peso.

Sheet Caso diario
A1: Asiento | B1: Fecha | C1: Cuenta | D1: Debe | E1: Haber | F1: Glosa | H1: Asiento | I1: Debe | J1: Haber | K1: Cuadra (0)
A2: 0 | B2: 01-03 | C2: Banco | D2: 4270000 | F2: Apertura con el balance al 1 de marzo | H2: 0 | I2: =SUMIF($A$2:$A$43,H2,$D$2:$D$43) | J2: =SUMIF($A$2:$A$43,H2,$E$2:$E$43) | K2: =I2-J2
A3: 0 | B3: 01-03 | C3: Clientes | D3: 1180000 | H3: 1 | I3: =SUMIF($A$2:$A$43,H3,$D$2:$D$43) | J3: =SUMIF($A$2:$A$43,H3,$E$2:$E$43) | K3: =I3-J3
A4: 0 | B4: 01-03 | C4: Poleras lisas básicas | D4: 2160000 | H4: 2 | I4: =SUMIF($A$2:$A$43,H4,$D$2:$D$43) | J4: =SUMIF($A$2:$A$43,H4,$E$2:$E$43) | K4: =I4-J4
A5: 0 | B5: 01-03 | C5: Tinta | D5: 198000 | H5: 3 | I5: =SUMIF($A$2:$A$43,H5,$D$2:$D$43) | J5: =SUMIF($A$2:$A$43,H5,$E$2:$E$43) | K5: =I5-J5
A6: 0 | B6: 01-03 | C6: Arriendo pagado por anticipado | D6: 580000 | H6: 4 | I6: =SUMIF($A$2:$A$43,H6,$D$2:$D$43) | J6: =SUMIF($A$2:$A$43,H6,$E$2:$E$43) | K6: =I6-J6
A7: 0 | B7: 01-03 | C7: Maquinaria | D7: 9840000 | H7: 5 | I7: =SUMIF($A$2:$A$43,H7,$D$2:$D$43) | J7: =SUMIF($A$2:$A$43,H7,$E$2:$E$43) | K7: =I7-J7
A8: 0 | B8: 01-03 | C8: Depreciación acumulada | E8: 2460000 | H8: 6 | I8: =SUMIF($A$2:$A$43,H8,$D$2:$D$43) | J8: =SUMIF($A$2:$A$43,H8,$E$2:$E$43) | K8: =I8-J8
A9: 0 | B9: 01-03 | C9: Proveedores | E9: 1340000 | H9: 7 | I9: =SUMIF($A$2:$A$43,H9,$D$2:$D$43) | J9: =SUMIF($A$2:$A$43,H9,$E$2:$E$43) | K9: =I9-J9
A10: 0 | B10: 01-03 | C10: Capital | E10: 14428000 | H10: 8 | I10: =SUMIF($A$2:$A$43,H10,$D$2:$D$43) | J10: =SUMIF($A$2:$A$43,H10,$E$2:$E$43) | K10: =I10-J10
A11: 1 | B11: 01-03 | C11: Poleras lisas básicas | D11: 5145000 | F11: Compra de poleras lisas básicas a crédito | H11: 9 | I11: =SUMIF($A$2:$A$43,H11,$D$2:$D$43) | J11: =SUMIF($A$2:$A$43,H11,$E$2:$E$43) | K11: =I11-J11
A12: 1 | B12: 01-03 | C12: IVA crédito fiscal | D12: 977550 | H12: 10 | I12: =SUMIF($A$2:$A$43,H12,$D$2:$D$43) | J12: =SUMIF($A$2:$A$43,H12,$E$2:$E$43) | K12: =I12-J12
A13: 1 | B13: 01-03 | C13: Proveedores | E13: 6122550 | H13: 11 | I13: =SUMIF($A$2:$A$43,H13,$D$2:$D$43) | J13: =SUMIF($A$2:$A$43,H13,$E$2:$E$43) | K13: =I13-J13
A14: 2 | B14: 01-03 | C14: Otras prendas lisas | D14: 10166980 | F14: Compra de las otras prendas lisas a crédito | H14: 12 | I14: =SUMIF($A$2:$A$43,H14,$D$2:$D$43) | J14: =SUMIF($A$2:$A$43,H14,$E$2:$E$43) | K14: =I14-J14
A15: 2 | B15: 01-03 | C15: IVA crédito fiscal | D15: 1931726
A16: 2 | B16: 01-03 | C16: Proveedores | E16: 12098706
A17: 3 | B17: 02-03 | C17: Tinta | D17: 1176731 | F17: Compra de tinta al contado
A18: 3 | B18: 02-03 | C18: IVA crédito fiscal | D18: 223579
A19: 3 | B19: 02-03 | C19: Banco | E19: 1400310
A20: 4 | B20: 04-03 | C20: Maquinaria | D20: 14300000 | F20: Compra de la segunda máquina
A21: 4 | B21: 04-03 | C21: IVA crédito fiscal | D21: 2717000
A22: 4 | B22: 04-03 | C22: Banco | E22: 8267000
A23: 4 | B23: 04-03 | C23: Documentos por pagar a largo plazo | E23: 8750000
A24: 5 | B24: 04-03 | C24: Banco | D24: 6400000 | F24: Préstamo bancario
A25: 5 | B25: 04-03 | C25: Préstamo bancario | E25: 6400000
A26: 6 | B26: 31-03 | C26: Banco | D26: 18368507 | F26: Ventas del mes
A27: 6 | B27: 31-03 | C27: Clientes | D27: 12245671
A28: 6 | B28: 31-03 | C28: Ventas | E28: 25726200
A29: 6 | B29: 31-03 | C29: IVA débito fiscal | E29: 4887978
A30: 7 | B30: 31-03 | C30: Sueldos | D30: 2880000 | F30: Pago de sueldos
A31: 7 | B31: 31-03 | C31: Banco | E31: 2880000
A32: 8 | B32: 31-03 | C32: Arriendo pagado por anticipado | D32: 1740000 | F32: Arriendo de abril a junio pagado por anticipado
A33: 8 | B33: 31-03 | C33: Banco | E33: 1740000
A34: 9 | B34: 31-03 | C34: Seguro pagado por anticipado | D34: 948000 | F34: Seguro anual pagado al contado
A35: 9 | B35: 31-03 | C35: IVA crédito fiscal | D35: 180120
A36: 9 | B36: 31-03 | C36: Banco | E36: 1128120
A37: 10 | B37: 31-03 | C37: Proveedores | D37: 1340000 | F37: Pago a proveedores del saldo inicial
A38: 10 | B38: 31-03 | C38: Banco | E38: 1340000
A39: 11 | B39: 31-03 | C39: Banco | D39: 1180000 | F39: Cobro a clientes del saldo inicial
A40: 11 | B40: 31-03 | C40: Clientes | E40: 1180000
...

Sheet Caso mayor
A1: Banco
A2: Asiento | B2: Debe | C2: Haber | D2: Saldo (Debe − Haber)
A3: ='Caso diario'!A2 | B3: ='Caso diario'!D2 | C3: ='Caso diario'!E2 | D3: =B3-C3
A4: ='Caso diario'!A19 | B4: ='Caso diario'!D19 | C4: ='Caso diario'!E19 | D4: =D3+B4-C4
A5: ='Caso diario'!A22 | B5: ='Caso diario'!D22 | C5: ='Caso diario'!E22 | D5: =D4+B5-C5
A6: ='Caso diario'!A24 | B6: ='Caso diario'!D24 | C6: ='Caso diario'!E24 | D6: =D5+B6-C6
A7: ='Caso diario'!A26 | B7: ='Caso diario'!D26 | C7: ='Caso diario'!E26 | D7: =D6+B7-C7
A8: ='Caso diario'!A31 | B8: ='Caso diario'!D31 | C8: ='Caso diario'!E31 | D8: =D7+B8-C8
A9: ='Caso diario'!A33 | B9: ='Caso diario'!D33 | C9: ='Caso diario'!E33 | D9: =D8+B9-C9
A10: ='Caso diario'!A36 | B10: ='Caso diario'!D36 | C10: ='Caso diario'!E36 | D10: =D9+B10-C10
A11: ='Caso diario'!A38 | B11: ='Caso diario'!D38 | C11: ='Caso diario'!E38 | D11: =D10+B11-C11
A12: ='Caso diario'!A39 | B12: ='Caso diario'!D39 | C12: ='Caso diario'!E39 | D12: =D11+B12-C12
A13: ='Caso diario'!A43 | B13: ='Caso diario'!D43 | C13: ='Caso diario'!E43 | D13: =D12+B13-C13
A14: Sumas | B14: =SUM(B3:B13) | C14: =SUM(C3:C13) | D14: =D13
A16: Clientes
A17: Asiento | B17: Debe | C17: Haber | D17: Saldo (Debe − Haber)
A18: ='Caso diario'!A3 | B18: ='Caso diario'!D3 | C18: ='Caso diario'!E3 | D18: =B18-C18
A19: ='Caso diario'!A27 | B19: ='Caso diario'!D27 | C19: ='Caso diario'!E27 | D19: =D18+B19-C19
A20: ='Caso diario'!A40 | B20: ='Caso diario'!D40 | C20: ='Caso diario'!E40 | D20: =D19+B20-C20
A21: Sumas | B21: =SUM(B18:B20) | C21: =SUM(C18:C20) | D21: =D20
A23: Poleras lisas básicas
A24: Asiento | B24: Debe | C24: Haber | D24: Saldo (Debe − Haber)
A25: ='Caso diario'!A4 | B25: ='Caso diario'!D4 | C25: ='Caso diario'!E4 | D25: =B25-C25
A26: ='Caso diario'!A11 | B26: ='Caso diario'!D11 | C26: ='Caso diario'!E11 | D26: =D25+B26-C26
A27: Sumas | B27: =SUM(B25:B26) | C27: =SUM(C25:C26) | D27: =D26
A29: Otras prendas lisas
A30: Asiento | B30: Debe | C30: Haber | D30: Saldo (Debe − Haber)
A31: ='Caso diario'!A14 | B31: ='Caso diario'!D14 | C31: ='Caso diario'!E14 | D31: =B31-C31
A32: Sumas | B32: =SUM(B31:B31) | C32: =SUM(C31:C31) | D32: =D31
A34: Tinta
A35: Asiento | B35: Debe | C35: Haber | D35: Saldo (Debe − Haber)
A36: ='Caso diario'!A5 | B36: ='Caso diario'!D5 | C36: ='Caso diario'!E5 | D36: =B36-C36
A37: ='Caso diario'!A17 | B37: ='Caso diario'!D17 | C37: ='Caso diario'!E17 | D37: =D36+B37-C37
A38: Sumas | B38: =SUM(B36:B37) | C38: =SUM(C36:C37) | D38: =D37
A40: IVA crédito fiscal
A41: Asiento | B41: Debe | C41: Haber | D41: Saldo (Debe − Haber)
A42: ='Caso diario'!A12 | B42: ='Caso diario'!D12 | C42: ='Caso diario'!E12 | D42: =B42-C42
A43: ='Caso diario'!A15 | B43: ='Caso diario'!D15 | C43: ='Caso diario'!E15 | D43: =D42+B43-C43
A44: ='Caso diario'!A18 | B44: ='Caso diario'!D18 | C44: ='Caso diario'!E18 | D44: =D43+B44-C44
A45: ='Caso diario'!A21 | B45: ='Caso diario'!D21 | C45: ='Caso diario'!E21 | D45: =D44+B45-C45
...

Sheet Caso comprobación
A1: Cuenta | B1: Sumas Debe | C1: Sumas Haber | D1: Saldo deudor | E1: Saldo acreedor
A2: Banco | B2: =SUMIF('Caso diario'!$C$2:$C$43,A2,'Caso diario'!$D$2:$D$43) | C2: =SUMIF('Caso diario'!$C$2:$C$43,A2,'Caso diario'!$E$2:$E$43) | D2: =MAX(B2-C2,0) | E2: =MAX(C2-B2,0)
A3: Clientes | B3: =SUMIF('Caso diario'!$C$2:$C$43,A3,'Caso diario'!$D$2:$D$43) | C3: =SUMIF('Caso diario'!$C$2:$C$43,A3,'Caso diario'!$E$2:$E$43) | D3: =MAX(B3-C3,0) | E3: =MAX(C3-B3,0)
A4: Poleras lisas básicas | B4: =SUMIF('Caso diario'!$C$2:$C$43,A4,'Caso diario'!$D$2:$D$43) | C4: =SUMIF('Caso diario'!$C$2:$C$43,A4,'Caso diario'!$E$2:$E$43) | D4: =MAX(B4-C4,0) | E4: =MAX(C4-B4,0)
A5: Otras prendas lisas | B5: =SUMIF('Caso diario'!$C$2:$C$43,A5,'Caso diario'!$D$2:$D$43) | C5: =SUMIF('Caso diario'!$C$2:$C$43,A5,'Caso diario'!$E$2:$E$43) | D5: =MAX(B5-C5,0) | E5: =MAX(C5-B5,0)
A6: Tinta | B6: =SUMIF('Caso diario'!$C$2:$C$43,A6,'Caso diario'!$D$2:$D$43) | C6: =SUMIF('Caso diario'!$C$2:$C$43,A6,'Caso diario'!$E$2:$E$43) | D6: =MAX(B6-C6,0) | E6: =MAX(C6-B6,0)
A7: IVA crédito fiscal | B7: =SUMIF('Caso diario'!$C$2:$C$43,A7,'Caso diario'!$D$2:$D$43) | C7: =SUMIF('Caso diario'!$C$2:$C$43,A7,'Caso diario'!$E$2:$E$43) | D7: =MAX(B7-C7,0) | E7: =MAX(C7-B7,0)
A8: Arriendo pagado por anticipado | B8: =SUMIF('Caso diario'!$C$2:$C$43,A8,'Caso diario'!$D$2:$D$43) | C8: =SUMIF('Caso diario'!$C$2:$C$43,A8,'Caso diario'!$E$2:$E$43) | D8: =MAX(B8-C8,0) | E8: =MAX(C8-B8,0)
A9: Seguro pagado por anticipado | B9: =SUMIF('Caso diario'!$C$2:$C$43,A9,'Caso diario'!$D$2:$D$43) | C9: =SUMIF('Caso diario'!$C$2:$C$43,A9,'Caso diario'!$E$2:$E$43) | D9: =MAX(B9-C9,0) | E9: =MAX(C9-B9,0)
A10: Maquinaria | B10: =SUMIF('Caso diario'!$C$2:$C$43,A10,'Caso diario'!$D$2:$D$43) | C10: =SUMIF('Caso diario'!$C$2:$C$43,A10,'Caso diario'!$E$2:$E$43) | D10: =MAX(B10-C10,0) | E10: =MAX(C10-B10,0)
A11: Depreciación acumulada | B11: =SUMIF('Caso diario'!$C$2:$C$43,A11,'Caso diario'!$D$2:$D$43) | C11: =SUMIF('Caso diario'!$C$2:$C$43,A11,'Caso diario'!$E$2:$E$43) | D11: =MAX(B11-C11,0) | E11: =MAX(C11-B11,0)
A12: Proveedores | B12: =SUMIF('Caso diario'!$C$2:$C$43,A12,'Caso diario'!$D$2:$D$43) | C12: =SUMIF('Caso diario'!$C$2:$C$43,A12,'Caso diario'!$E$2:$E$43) | D12: =MAX(B12-C12,0) | E12: =MAX(C12-B12,0)
A13: IVA débito fiscal | B13: =SUMIF('Caso diario'!$C$2:$C$43,A13,'Caso diario'!$D$2:$D$43) | C13: =SUMIF('Caso diario'!$C$2:$C$43,A13,'Caso diario'!$E$2:$E$43) | D13: =MAX(B13-C13,0) | E13: =MAX(C13-B13,0)
... A19: Gastos de administración | B19: =SUMIF('Caso diario'!$C$2:$C$43,A19,'Caso diario'!$D$2:$D$43) | C19: =SUMIF('Caso diario'!$C$2:$C$43,A19,'Caso diario'!$E$2:$E$43) | D19: =MAX(B19-C19,0) | E19: =MAX(C19-B19,0)
A20: Totales | B20: =SUM(B2:B19) | C20: =SUM(C2:C19) | D20: =SUM(D2:D19) | E20: =SUM(E2:E19)
A21: Sumas iguales (0) | B21: =B20-C20 | D21: =D20-E20

Sheet Ejemplo diario
A1: Asiento | B1: Fecha | C1: Cuenta | D1: Debe | E1: Haber | F1: Glosa | H1: Asiento | I1: Debe | J1: Haber | K1: Cuadra (0)
A2: 1 | B2: 02-05-2026 | C2: Banco | D2: 7400000 | F2: Aporte inicial de Fernanda | H2: 1 | I2: =SUMIF($A$2:$A$28,H2,$D$2:$D$28) | J2: =SUMIF($A$2:$A$28,H2,$E$2:$E$28) | K2: =I2-J2
A3: 1 | B3: 02-05-2026 | C3: Capital | E3: 7400000 | H3: 2 | I3: =SUMIF($A$2:$A$28,H3,$D$2:$D$28) | J3: =SUMIF($A$2:$A$28,H3,$E$2:$E$28) | K3: =I3-J3
A4: 2 | B4: 03-05-2026 | C4: Maquinaria | D4: 3260000 | F4: Compra de dos impresoras, mitad al contado y mitad a 60 días | H4: 3 | I4: =SUMIF($A$2:$A$28,H4,$D$2:$D$28) | J4: =SUMIF($A$2:$A$28,H4,$E$2:$E$28) | K4: =I4-J4
A5: 2 | B5: 03-05-2026 | C5: IVA crédito fiscal | D5: 619400 | H5: 4 | I5: =SUMIF($A$2:$A$28,H5,$D$2:$D$28) | J5: =SUMIF($A$2:$A$28,H5,$E$2:$E$28) | K5: =I5-J5
A6: 2 | B6: 03-05-2026 | C6: Banco | E6: 1939700 | H6: 5 | I6: =SUMIF($A$2:$A$28,H6,$D$2:$D$28) | J6: =SUMIF($A$2:$A$28,H6,$E$2:$E$28) | K6: =I6-J6
A7: 2 | B7: 03-05-2026 | C7: Cuentas por pagar | E7: 1939700 | H7: 6 | I7: =SUMIF($A$2:$A$28,H7,$D$2:$D$28) | J7: =SUMIF($A$2:$A$28,H7,$E$2:$E$28) | K7: =I7-J7
A8: 3 | B8: 05-05-2026 | C8: Materiales | D8: 870000 | F8: Compra de filamento a crédito del proveedor | H8: 7 | I8: =SUMIF($A$2:$A$28,H8,$D$2:$D$28) | J8: =SUMIF($A$2:$A$28,H8,$E$2:$E$28) | K8: =I8-J8
A9: 3 | B9: 05-05-2026 | C9: IVA crédito fiscal | D9: 165300 | H9: 8 | I9: =SUMIF($A$2:$A$28,H9,$D$2:$D$28) | J9: =SUMIF($A$2:$A$28,H9,$E$2:$E$28) | K9: =I9-J9
A10: 3 | B10: 05-05-2026 | C10: Proveedores | E10: 1035300 | H10: 9 | I10: =SUMIF($A$2:$A$28,H10,$D$2:$D$28) | J10: =SUMIF($A$2:$A$28,H10,$E$2:$E$28) | K10: =I10-J10
A11: 4 | B11: 06-05-2026 | C11: Arriendo | D11: 365000 | F11: Arriendo de mayo y junio pagado por transferencia | H11: 10 | I11: =SUMIF($A$2:$A$28,H11,$D$2:$D$28) | J11: =SUMIF($A$2:$A$28,H11,$E$2:$E$28) | K11: =I11-J11
A12: 4 | B12: 06-05-2026 | C12: Arriendo pagado por anticipado | D12: 365000
A13: 4 | B13: 06-05-2026 | C13: Banco | E13: 730000
A14: 5 | B14: 20-05-2026 | C14: Banco | D14: 906780 | F14: Venta de piezas, 30 % por transferencia y el resto a crédito
A15: 5 | B15: 20-05-2026 | C15: Clientes | D15: 2115820
A16: 5 | B16: 20-05-2026 | C16: Ventas | E16: 2540000
A17: 5 | B17: 20-05-2026 | C17: IVA débito fiscal | E17: 482600
A18: 6 | B18: 20-05-2026 | C18: Costo de ventas | D18: 510000 | F18: Costo del filamento de las piezas vendidas
A19: 6 | B19: 20-05-2026 | C19: Materiales | E19: 510000
A20: 7 | B20: 31-05-2026 | C20: Sueldos | D20: 1150000 | F20: Sueldos de mayo pagados
A21: 7 | B21: 31-05-2026 | C21: Banco | E21: 1150000
A22: 8 | B22: 31-05-2026 | C22: Proveedores | D22: 640000 | F22: Abono a proveedores
A23: 8 | B23: 31-05-2026 | C23: Banco | E23: 640000
A24: 9 | B24: 31-05-2026 | C24: Banco | D24: 1050000 | F24: Cobro a clientes
A25: 9 | B25: 31-05-2026 | C25: Clientes | E25: 1050000
A26: 10 | B26: 31-05-2026 | C26: Electricidad | D26: 64000 | F26: Cuenta de luz de mayo, se paga en junio
A27: 10 | B27: 31-05-2026 | C27: IVA crédito fiscal | D27: 12160
A28: 10 | B28: 31-05-2026 | C28: Cuentas por pagar | E28: 76160
C30: Totales | D30: =SUM(D2:D28) | E30: =SUM(E2:E28)
C31: Diferencia (debe dar 0) | D31: =D30-E30

Sheet Ejemplo mayor
A1: Banco
A2: Asiento | B2: Debe | C2: Haber | D2: Saldo (Debe − Haber)
A3: ='Ejemplo diario'!A2 | B3: ='Ejemplo diario'!D2 | C3: ='Ejemplo diario'!E2 | D3: =B3-C3
A4: ='Ejemplo diario'!A6 | B4: ='Ejemplo diario'!D6 | C4: ='Ejemplo diario'!E6 | D4: =D3+B4-C4
A5: ='Ejemplo diario'!A13 | B5: ='Ejemplo diario'!D13 | C5: ='Ejemplo diario'!E13 | D5: =D4+B5-C5
A6: ='Ejemplo diario'!A14 | B6: ='Ejemplo diario'!D14 | C6: ='Ejemplo diario'!E14 | D6: =D5+B6-C6
A7: ='Ejemplo diario'!A21 | B7: ='Ejemplo diario'!D21 | C7: ='Ejemplo diario'!E21 | D7: =D6+B7-C7
A8: ='Ejemplo diario'!A23 | B8: ='Ejemplo diario'!D23 | C8: ='Ejemplo diario'!E23 | D8: =D7+B8-C8
A9: ='Ejemplo diario'!A24 | B9: ='Ejemplo diario'!D24 | C9: ='Ejemplo diario'!E24 | D9: =D8+B9-C9
A10: Sumas | B10: =SUM(B3:B9) | C10: =SUM(C3:C9) | D10: =D9
A12: Clientes
A13: Asiento | B13: Debe | C13: Haber | D13: Saldo (Debe − Haber)
A14: ='Ejemplo diario'!A15 | B14: ='Ejemplo diario'!D15 | C14: ='Ejemplo diario'!E15 | D14: =B14-C14
A15: ='Ejemplo diario'!A25 | B15: ='Ejemplo diario'!D25 | C15: ='Ejemplo diario'!E25 | D15: =D14+B15-C15
A16: Sumas | B16: =SUM(B14:B15) | C16: =SUM(C14:C15) | D16: =D15
A18: Materiales
A19: Asiento | B19: Debe | C19: Haber | D19: Saldo (Debe − Haber)
A20: ='Ejemplo diario'!A8 | B20: ='Ejemplo diario'!D8 | C20: ='Ejemplo diario'!E8 | D20: =B20-C20
A21: ='Ejemplo diario'!A19 | B21: ='Ejemplo diario'!D19 | C21: ='Ejemplo diario'!E19 | D21: =D20+B21-C21
A22: Sumas | B22: =SUM(B20:B21) | C22: =SUM(C20:C21) | D22: =D21
A24: IVA crédito fiscal
A25: Asiento | B25: Debe | C25: Haber | D25: Saldo (Debe − Haber)
A26: ='Ejemplo diario'!A5 | B26: ='Ejemplo diario'!D5 | C26: ='Ejemplo diario'!E5 | D26: =B26-C26
A27: ='Ejemplo diario'!A9 | B27: ='Ejemplo diario'!D9 | C27: ='Ejemplo diario'!E9 | D27: =D26+B27-C27
A28: ='Ejemplo diario'!A27 | B28: ='Ejemplo diario'!D27 | C28: ='Ejemplo diario'!E27 | D28: =D27+B28-C28
A29: Sumas | B29: =SUM(B26:B28) | C29: =SUM(C26:C28) | D29: =D28
A31: Arriendo pagado por anticipado
A32: Asiento | B32: Debe | C32: Haber | D32: Saldo (Debe − Haber)
A33: ='Ejemplo diario'!A12 | B33: ='Ejemplo diario'!D12 | C33: ='Ejemplo diario'!E12 | D33: =B33-C33
A34: Sumas | B34: =SUM(B33:B33) | C34: =SUM(C33:C33) | D34: =D33
A36: Maquinaria
A37: Asiento | B37: Debe | C37: Haber | D37: Saldo (Debe − Haber)
A38: ='Ejemplo diario'!A4 | B38: ='Ejemplo diario'!D4 | C38: ='Ejemplo diario'!E4 | D38: =B38-C38
A39: Sumas | B39: =SUM(B38:B38) | C39: =SUM(C38:C38) | D39: =D38
A41: Proveedores
A42: Asiento | B42: Debe | C42: Haber | D42: Saldo (Debe − Haber)
A43: ='Ejemplo diario'!A10 | B43: ='Ejemplo diario'!D10 | C43: ='Ejemplo diario'!E10 | D43: =B43-C43
A44: ='Ejemplo diario'!A22 | B44: ='Ejemplo diario'!D22 | C44: ='Ejemplo diario'!E22 | D44: =D43+B44-C44
A45: Sumas | B45: =SUM(B43:B44) | C45: =SUM(C43:C44) | D45: =D44
A47: Cuentas por pagar
...

Sheet Ejemplo comprobación
A1: Cuenta | B1: Sumas Debe | C1: Sumas Haber | D1: Saldo deudor | E1: Saldo acreedor
A2: Banco | B2: =SUMIF('Ejemplo diario'!$C$2:$C$28,A2,'Ejemplo diario'!$D$2:$D$28) | C2: =SUMIF('Ejemplo diario'!$C$2:$C$28,A2,'Ejemplo diario'!$E$2:$E$28) | D2: =MAX(B2-C2,0) | E2: =MAX(C2-B2,0)
A3: Clientes | B3: =SUMIF('Ejemplo diario'!$C$2:$C$28,A3,'Ejemplo diario'!$D$2:$D$28) | C3: =SUMIF('Ejemplo diario'!$C$2:$C$28,A3,'Ejemplo diario'!$E$2:$E$28) | D3: =MAX(B3-C3,0) | E3: =MAX(C3-B3,0)
A4: Materiales | B4: =SUMIF('Ejemplo diario'!$C$2:$C$28,A4,'Ejemplo diario'!$D$2:$D$28) | C4: =SUMIF('Ejemplo diario'!$C$2:$C$28,A4,'Ejemplo diario'!$E$2:$E$28) | D4: =MAX(B4-C4,0) | E4: =MAX(C4-B4,0)
A5: IVA crédito fiscal | B5: =SUMIF('Ejemplo diario'!$C$2:$C$28,A5,'Ejemplo diario'!$D$2:$D$28) | C5: =SUMIF('Ejemplo diario'!$C$2:$C$28,A5,'Ejemplo diario'!$E$2:$E$28) | D5: =MAX(B5-C5,0) | E5: =MAX(C5-B5,0)
A6: Arriendo pagado por anticipado | B6: =SUMIF('Ejemplo diario'!$C$2:$C$28,A6,'Ejemplo diario'!$D$2:$D$28) | C6: =SUMIF('Ejemplo diario'!$C$2:$C$28,A6,'Ejemplo diario'!$E$2:$E$28) | D6: =MAX(B6-C6,0) | E6: =MAX(C6-B6,0)
A7: Maquinaria | B7: =SUMIF('Ejemplo diario'!$C$2:$C$28,A7,'Ejemplo diario'!$D$2:$D$28) | C7: =SUMIF('Ejemplo diario'!$C$2:$C$28,A7,'Ejemplo diario'!$E$2:$E$28) | D7: =MAX(B7-C7,0) | E7: =MAX(C7-B7,0)
A8: Proveedores | B8: =SUMIF('Ejemplo diario'!$C$2:$C$28,A8,'Ejemplo diario'!$D$2:$D$28) | C8: =SUMIF('Ejemplo diario'!$C$2:$C$28,A8,'Ejemplo diario'!$E$2:$E$28) | D8: =MAX(B8-C8,0) | E8: =MAX(C8-B8,0)
A9: Cuentas por pagar | B9: =SUMIF('Ejemplo diario'!$C$2:$C$28,A9,'Ejemplo diario'!$D$2:$D$28) | C9: =SUMIF('Ejemplo diario'!$C$2:$C$28,A9,'Ejemplo diario'!$E$2:$E$28) | D9: =MAX(B9-C9,0) | E9: =MAX(C9-B9,0)
A10: IVA débito fiscal | B10: =SUMIF('Ejemplo diario'!$C$2:$C$28,A10,'Ejemplo diario'!$D$2:$D$28) | C10: =SUMIF('Ejemplo diario'!$C$2:$C$28,A10,'Ejemplo diario'!$E$2:$E$28) | D10: =MAX(B10-C10,0) | E10: =MAX(C10-B10,0)
A11: Capital | B11: =SUMIF('Ejemplo diario'!$C$2:$C$28,A11,'Ejemplo diario'!$D$2:$D$28) | C11: =SUMIF('Ejemplo diario'!$C$2:$C$28,A11,'Ejemplo diario'!$E$2:$E$28) | D11: =MAX(B11-C11,0) | E11: =MAX(C11-B11,0)
A12: Ventas | B12: =SUMIF('Ejemplo diario'!$C$2:$C$28,A12,'Ejemplo diario'!$D$2:$D$28) | C12: =SUMIF('Ejemplo diario'!$C$2:$C$28,A12,'Ejemplo diario'!$E$2:$E$28) | D12: =MAX(B12-C12,0) | E12: =MAX(C12-B12,0)
A13: Costo de ventas | B13: =SUMIF('Ejemplo diario'!$C$2:$C$28,A13,'Ejemplo diario'!$D$2:$D$28) | C13: =SUMIF('Ejemplo diario'!$C$2:$C$28,A13,'Ejemplo diario'!$E$2:$E$28) | D13: =MAX(B13-C13,0) | E13: =MAX(C13-B13,0)
... A16: Electricidad | B16: =SUMIF('Ejemplo diario'!$C$2:$C$28,A16,'Ejemplo diario'!$D$2:$D$28) | C16: =SUMIF('Ejemplo diario'!$C$2:$C$28,A16,'Ejemplo diario'!$E$2:$E$28) | D16: =MAX(B16-C16,0) | E16: =MAX(C16-B16,0)
A17: Totales | B17: =SUM(B2:B16) | C17: =SUM(C2:C16) | D17: =SUM(D2:D16) | E17: =SUM(E2:E16)
A18: Sumas iguales (0) | B18: =B17-C17 | D18: =D17-E17
